<?xml version="1.0"?>
<robot name="walle">
    <!-- Define Gazebo colors and plugins -->
    <gazebo>
        <plugin name="differential_drive_controller" filename="libgazebo_ros_diff_drive.so">
            <ros>
                <namespace>/walle</namespace>
            </ros>
            <left_joint>base_to_left_wheel</left_joint>
            <right_joint>base_to_right_wheel</right_joint>
            <wheel_separation>0.2</wheel_separation> <!-- Distance between wheels -->
            <wheel_diameter>0.1</wheel_diameter> <!-- Diameter of the wheels -->
            <max_wheel_torque>10.0</max_wheel_torque>
            <max_wheel_acceleration>5.0</max_wheel_acceleration>
            <publish_odom>true</publish_odom>
            <publish_odom_tf>true</publish_odom_tf>
            <odometry_frame>odom</odometry_frame>
            <robot_base_frame>base_link</robot_base_frame>
            <command_topic>cmd_vel</command_topic>
            <odometry_topic>odom</odometry_topic>
        </plugin>
    </gazebo>

    <!-- Base Link -->
    <link name="base_link">
        <visual>
            <geometry>
                <cylinder length="0.1" radius="0.2"/>
            </geometry>
            <material name="black">
                <color rgba="0 0 0 1"/>
            </material>
        </visual>
        <collision>
            <geometry>
                <cylinder length="0.1" radius="0.2"/>
            </geometry>
        </collision>
        <inertial>
            <mass value="1.0"/>
            <inertia ixx="0.01" ixy="0.0" ixz="0.0" iyy="0.01" iyz="0.0" izz="0.01"/>
        </inertial>
    </link>

    <!-- Left Wheel -->
    <link name="left_wheel">
        <visual>
            <geometry>
                <cylinder length="0.05" radius="0.05"/>
            </geometry>
            <material name="gray">
                <color rgba="0.5 0.5 0.5 1"/>
            </material>
        </visual>
        <collision>
            <geometry>
                <cylinder length="0.05" radius="0.05"/>
            </geometry>
        </collision>
        <inertial>
            <mass value="0.1"/>
            <inertia ixx="0.001" ixy="0.0" ixz="0.0" iyy="0.001" iyz="0.0" izz="0.001"/>
        </inertial>
    </link>

    <!-- Right Wheel -->
    <link name="right_wheel">
        <visual>
            <geometry>
                <cylinder length="0.05" radius="0.05"/>
            </geometry>
            <material name="gray">
                <color rgba="0.5 0.5 0.5 1"/>
            </material>
        </visual>
        <collision>
            <geometry>
                <cylinder length="0.05" radius="0.05"/>
            </geometry>
        </collision>
        <inertial>
            <mass value="0.1"/>
            <inertia ixx="0.001" ixy="0.0" ixz="0.0" iyy="0.001" iyz="0.0" izz="0.001"/>
        </inertial>
    </link>

    <!-- Caster -->
    <link name="caster">
        <visual>
            <geometry>
                <sphere radius="0.02"/>
            </geometry>
            <material name="white">
                <color rgba="1 1 1 1"/>
            </material>
        </visual>
        <collision>
            <geometry>
                <sphere radius="0.02"/>
            </geometry>
        </collision>
        <inertial>
            <mass value="0.01"/>
            <inertia ixx="0.0001" ixy="0.0" ixz="0.0" iyy="0.0001" iyz="0.0" izz="0.0001"/>
        </inertial>
    </link>

    <!-- Joints -->
    <joint name="base_to_left_wheel" type="continuous">
        <parent link="base_link"/>
        <child link="left_wheel"/>
        <origin xyz="-0.1 0.25 0" rpy="1.5708 0 0"/>
        <axis xyz="0 1 0"/>
    </joint>

    <joint name="base_to_right_wheel" type="continuous">
        <parent link="base_link"/>
        <child link="right_wheel"/>
        <origin xyz="0.1 0.25 0" rpy="1.5708 0 0"/>
        <axis xyz="0 1 0"/>
    </joint>

    <joint name="base_to_caster" type="fixed">
        <parent link="base_link"/>
        <child link="caster"/>
        <origin xyz="0 -0.15 -0.05" rpy="0 0 0"/>
    </joint>
</robot>
