<?xml version="1.0"?>
<robot name="walle">
  <!-- Link da base -->
  <link name="base_link">
    <visual>
      <geometry>
        <cylinder radius="0.2" length="0.1"/>
      </geometry>
      <material name="silver">
        <color rgba="0.7 0.7 0.7 1.0"/>
      </material>
    </visual>
    <collision>
      <geometry>
        <cylinder radius="0.2" length="0.1"/>
      </geometry>
    </collision>
    <inertial>
      <mass value="5.0"/>
      <inertia ixx="0.1" ixy="0.0" ixz="0.0" iyy="0.1" iyz="0.0" izz="0.05"/>
    </inertial>
  </link>

  <!-- Roda esquerda -->
  <link name="left_wheel">
    <visual>
      <geometry>
        <cylinder radius="0.05" length="0.02"/>
      </geometry>
      <material name="black">
        <color rgba="0.1 0.1 0.1 1.0"/>
      </material>
    </visual>
    <collision>
      <geometry>
        <cylinder radius="0.05" length="0.02"/>
      </geometry>
    </collision>
    <inertial>
      <mass value="0.2"/>
      <inertia ixx="0.001" ixy="0.0" ixz="0.0" iyy="0.001" iyz="0.0" izz="0.0005"/>
    </inertial>
  </link>

  <!-- Joint da roda esquerda -->
  <joint name="left_wheel_joint" type="continuous">
    <parent link="base_link"/>
    <child link="left_wheel"/>
    <origin xyz="0.0 0.15 -0.05" rpy="1.5708 0 0"/>
    <axis xyz="0 0 1"/> <!-- Girar em torno do eixo X global (eixo base-tampa do cilindro) -->
  </joint>

  <!-- Roda direita -->
  <link name="right_wheel">
    <visual>
      <geometry>
        <cylinder radius="0.05" length="0.02"/>
      </geometry>
      <material name="black"/>
    </visual>
    <collision>
      <geometry>
        <cylinder radius="0.05" length="0.02"/>
      </geometry>
    </collision>
    <inertial>
      <mass value="0.2"/>
      <inertia ixx="0.001" ixy="0.0" ixz="0.0" iyy="0.001" iyz="0.0" izz="0.0005"/>
    </inertial>
  </link>

  <!-- Joint da roda direita -->
  <joint name="right_wheel_joint" type="continuous">
    <parent link="base_link"/>
    <child link="right_wheel"/>
    <origin xyz="0.0 -0.15 -0.05" rpy="1.5708 0 0"/>
    <axis xyz="0 0 1"/> <!-- Girar em torno do eixo X global (eixo base-tampa do cilindro) -->
  </joint>

  <!-- Roda caster traseira -->
  <link name="caster_wheel">
    <visual>
      <geometry>
        <sphere radius="0.02"/>
      </geometry>
      <material name="white">
        <color rgba="1.0 1.0 1.0 1.0"/>
      </material>
    </visual>
    <collision>
      <geometry>
        <sphere radius="0.02"/>
      </geometry>
    </collision>
    <inertial>
      <mass value="0.1"/>
      <inertia ixx="0.0001" ixy="0.0" ixz="0.0" iyy="0.0001" iyz="0.0" izz="0.0001"/>
    </inertial>
  </link>

  <!-- Joint da roda caster -->
  <joint name="caster_joint" type="fixed">
    <parent link="base_link"/>
    <child link="caster_wheel"/>
    <origin xyz="-0.15 0 -0.08" rpy="0 0 0"/>
  </joint>
</robot>
